<?xml version="1.0"?>


<robot name="quadrotor">

<material name="blue">
  <color rgba="0.0 0.0 0.8 1.0"/>
</material>
<material name="white">
  <color rgba="1 1 1 1"/>
</material>


  <link name = "/robot1/base_footprint">
    <visual>
      <origin xyz="0 0 0" rpy="1.57 0 0"/>
      <geometry>
       <mesh filename="package://turtlebot_launch/meshes/met.STL" scale="1 1 1"/>
<!--<cylinder radius="0.2" length="0.4"/>-->
      </geometry>
    </visual>
  </link>

<joint name="/robot1/leg1" type="fixed">
<parent link="/robot1/base_footprint"/>
<child link="/robot1/leg1"/>
<origin xyz="0.1075 -0.1575 -0.0975"/>
</joint>

  <link name = "/robot1/leg1">
    <visual>
	<origin xyz="0 0 0" rpy="1.57 0 0"/>
      <geometry>
       <mesh filename="package://turtlebot_launch/meshes/leg1.STL" scale="1 1 1"/>
      </geometry>
	<material name="blue"/>
    </visual>
  </link>

<joint name="/robot1/leg2" type="fixed">
<parent link="/robot1/base_footprint"/>
<child link="/robot1/leg2"/>
<origin xyz="0.1075 -0.1575 -0.0975"/>
</joint>

  <link name = "/robot1/leg2">
    <visual>
	<origin xyz="0 0 0" rpy="1.57 0 1.57"/>
      <geometry>
       <mesh filename="package://turtlebot_launch/meshes/leg1.STL" scale="1 1 1"/>
      </geometry>
	<material name="blue"/>
    </visual>
  </link>


<joint name="/robot1/leg3" type="fixed">
<parent link="/robot1/base_footprint"/>
<child link="/robot1/leg3"/>
<origin xyz="0.1075 -0.1575 -0.0975"/>
</joint>

  <link name = "/robot1/leg3">
    <visual>
	<origin xyz="0 0 0" rpy="1.57 0 3.14 "/>
      <geometry>
       <mesh filename="package://turtlebot_launch/meshes/leg1.STL" scale="1 1 1"/>
      </geometry>
	<material name="blue"/>
    </visual>
  </link>

<joint name="/robot1/leg4" type="fixed">
<parent link="/robot1/base_footprint"/>
<child link="/robot1/leg4"/>
<origin xyz="0.1075 -0.1575 -0.0975"/>
</joint>

  <link name = "/robot1/leg4">
    <visual>
	<origin xyz="0 0 0" rpy="1.57 0 -1.57 "/>
      <geometry>
       <mesh filename="package://turtlebot_launch/meshes/leg1.STL" scale="1 1 1"/>
      </geometry>
	<material name="blue"/>
    </visual>
  </link>

<joint name="/robot1/prop1" type="continuous">
<parent link="/robot1/leg1"/>
<child link="/robot1/prop1"/>
<axis xyz ="0 0 1"/>
<origin xyz="0.23 -0.23 0.2175"/>
</joint>

  <link name = "/robot1/prop1">
    <visual>
	<origin xyz="0 0 0" rpy="0 0 0 "/>
      <geometry>
       <box size = "0.2 0.025 0.0125"/>
      </geometry>
	<material name="white"/>
    </visual>
  </link>

<joint name="/robot1/prop2" type="continuous">
<parent link="/robot1/leg2"/>
<child link="/robot1/prop2"/>
<axis xyz ="0 0 1"/>
<origin xyz="0.23 0.23 0.2175"/>
</joint>

  <link name = "/robot1/prop2">
    <visual>
	<origin xyz="0 0 0" rpy="0 0 0 "/>
      <geometry>
       <box size = "0.2 0.025 0.0125"/>
      </geometry>
	<material name="white"/>
    </visual>
  </link>

<joint name="/robot1/prop3" type="continuous">
<parent link="/robot1/leg3"/>
<child link="/robot1/prop3"/>
<axis xyz ="0 0 1"/>
<origin xyz="-0.23 0.23 0.2175"/>
</joint>

  <link name = "/robot1/prop3">
    <visual>
	<origin xyz="0 0 0" rpy="0 0 0 "/>
      <geometry>
       <box size = "0.2 0.025 0.0125"/>
      </geometry>
	<material name="white"/>
    </visual>
  </link>

<joint name="/robot1/prop4" type="continuous">
<parent link="/robot1/leg4"/>
<child link="/robot1/prop4"/>
<axis xyz ="0 0 1"/>
<origin xyz="-0.23 -0.23 0.2175"/>
</joint>

  <link name = "/robot1/prop4">
    <visual>
	<origin xyz="0 0 0" rpy="0 0 0 "/>
      <geometry>
       <box size = "0.2 0.025 0.0125"/>
      </geometry>
	<material name="white"/>
    </visual>
  </link>


</robot>
